Workbook

Sheet Summary
A1: Policy Alpha Research
A2: EHang Public-Source DCF Model
A3: Policy Alpha Research commercialization stress test. Uses public company filings, company IR releases, and public market context. Not investment advice.
A5: Scenario | B5: Implied Equity Value / ADS | C5: Upside / Downside vs Market | D5: Core Interpretation
A6: Bear | B6: ='Valuation Output'!B5 | C6: ='Valuation Output'!C5 | D6: Certification progress does not convert quickly into scaled operations; FCF remains delayed.
A7: Base | B7: ='Valuation Output'!B6 | C7: ='Valuation Output'!C6 | D7: Commercial deployment scales gradually; operating leverage improves but remains execution-dependent.
A8: Bull | B8: ='Valuation Output'!B7 | C8: ='Valuation Output'!C7 | D8: Policy support, city pilots and route economics translate into faster recurring operating visibility.
A10: Key Model Message
A11: The model is most sensitive to whether EHang can move beyond certified aircraft deliveries into repeatable operations, route utilization, operating leverage, and free-cash-flow conversion.
A13: Current Market Inputs
A14: Market price / ADS | B14: =Inputs!B4 | C14: Editable in Inputs; current seed from public quote summary
A15: ADS equivalent shares | B15: =Inputs!B7 | C15: Ordinary shares divided by two ordinary shares per ADS
A16: Net cash used in model | B16: =Inputs!B8/Inputs!B10 | C16: RMB cash converted to USD; debt set to zero unless updated
A17: FY2026 company revenue outlook | B17: =Inputs!B16 | C17: Company outlook: around RMB600m
A19: Important Boundary
A20: This workbook is an educational valuation framework based on public information. It is not a recommendation, not personal advice, not a securities research recommendation, and not a solicitation to trade EH or any security.

Sheet Inputs
A1: Inputs
A2: Update the yellow cells when new quarterly results or market data are available.
A4: Market price / ADS (USD) | B4: 8.71 | C4: MarketScreener summary, 2026-06-08 close / estimate reference
A5: Ordinary shares outstanding | B5: 150242174 | C5: 2025 Form 20-F, ordinary shares outstanding at Dec 31 2025
A6: Ordinary shares per ADS | B6: 2 | C6: Each ADS represents two Class A ordinary shares
A7: ADS equivalent shares | B7: =B5/B6 | C7: Calculated
A8: Cash, restricted deposits and short-term investments (RMB) | B8: 1130000000 | C8: FY2025 result
A9: Debt used in model (USD) | B9: 0 | C9: Set to zero pending full debt schedule; update if needed
A10: RMB / USD | B10: 6.9931 | C10: 2025 Form 20-F translation rate
A11: Cash tax rate | B11: 0.25 | C11: Illustrative long-term tax rate
A12: FY2025 revenue (RMB m) | B12: 509.5 | C12: FY2025 reported revenue
A13: FY2025 gross margin | B13: 0.62 | C13: FY2025 reported gross margin
A14: FY2025 operating loss (RMB m) | B14: -266.3 | C14: FY2025 reported operating loss
A15: FY2025 net loss (RMB m) | B15: -231 | C15: FY2025 reported net loss
A16: FY2026 revenue outlook (RMB m) | B16: 600 | C16: Company outlook from FY2025 results release: around RMB600m
A17: FY2025 deliveries | B17: 221 | C17: 215 EH216 series + 6 VT35
A18: Q4 2025 deliveries | B18: 100 | C18: 95 EH216 series + 5 VT35
A19: Q4 2025 revenue (RMB m) | B19: 243.8 | C19: Record quarterly revenue
... A21: Q4 2025 net income (RMB m) | B21: 10.5 | C21: First GAAP profitable quarter
A23: Scenario Assumptions | B23: Bear | C23: Base | D23: Bull
A24: 2026E Revenue (RMB m) | B24: 500 | C24: 600 | D24: 750
A25: 2027 Growth | B25: 0.15 | C25: 0.4 | D25: 0.65
A26: 2028 Growth | B26: 0.15 | C26: 0.35 | D26: 0.55
A27: 2029 Growth | B27: 0.12 | C27: 0.3 | D27: 0.45
A28: 2030 Growth | B28: 0.1 | C28: 0.25 | D28: 0.35
A29: Long-term Gross Margin | B29: 0.58 | C29: 0.6 | D29: 0.62
A30: 2030E Operating Expense / Revenue | B30: 0.5 | C30: 0.38 | D30: 0.3
A31: D&A / Revenue | B31: 0.02 | C31: 0.025 | D31: 0.03
A32: Capex / Revenue | B32: 0.08 | C32: 0.07 | D32: 0.06
A33: NWC / Revenue Change | B33: 0.08 | C33: 0.06 | D33: 0.05
A34: Discount Rate | B34: 0.14 | C34: 0.13 | D34: 0.12
A35: Terminal Growth | B35: 0.025 | C35: 0.03 | D35: 0.035
A37: Public Source Notes
A38: FY2025: revenue RMB509.5m, gross margin 62.0%, operating loss RMB266.3m, net loss RMB231.0m, cash/investments RMB1.13bn, deliveries 221 units.
A39: Q4 2025: revenue RMB243.8m, gross margin 62.1%, operating loss RMB6.6m, net income RMB10.5m, deliveries 100 units.
A40: FY2026 company outlook: total revenues around RMB600m, about 18% year-over-year growth. Base case deliberately anchors to this public guide before applying longer-term commercialization assumptions.

Sheet DCF Model
A1: DCF Model - RMB millions unless noted
A3: Bear Case | B3: 2025A | C3: 2026E | D3: 2027E | E3: 2028E | F3: 2029E | G3: 2030E
A4: Revenue | B4: =Inputs!B12 | C4: =Inputs!B24 | D4: =C4*(1+Inputs!B25) | E4: =D4*(1+Inputs!B26) | F4: =E4*(1+Inputs!B27) | G4: =F4*(1+Inputs!B28)
A5: Revenue Growth | B5: n.a. | C5: =C4/B4-1 | D5: =D4/C4-1 | E5: =E4/D4-1 | F5: =F4/E4-1 | G5: =G4/F4-1
A6: Gross Margin | B6: =Inputs!B13 | C6: =Inputs!B29 | D6: =Inputs!B29 | E6: =Inputs!B29 | F6: =Inputs!B29 | G6: =Inputs!B29
A7: Gross Profit | B7: =B4*B6 | C7: =C4*C6 | D7: =D4*D6 | E7: =E4*E6 | F7: =F4*F6 | G7: =G4*G6
A8: Operating Expense / Revenue | B8: =(Inputs!B12*Inputs!B13-Inputs!B14)/Inputs!B12 | C8: =((B8)*0.85+Inputs!B30*0.15) | D8: =((C8)*0.65+Inputs!B30*0.35) | E8: =((D8)*0.45+Inputs!B30*0.55) | F8: =((E8)*0.25+Inputs!B30*0.75) | G8: =Inputs!B30
A9: Operating Expense | B9: =B4*B8 | C9: =C4*C8 | D9: =D4*D8 | E9: =E4*E8 | F9: =F4*F8 | G9: =G4*G8
A10: EBIT | B10: =B7-B9 | C10: =C7-C9 | D10: =D7-D9 | E10: =E7-E9 | F10: =F7-F9 | G10: =G7-G9
A11: Tax on Positive EBIT | B11: 0 | C11: =MAX(0,C10*Inputs!B11) | D11: =MAX(0,D10*Inputs!B11) | E11: =MAX(0,E10*Inputs!B11) | F11: =MAX(0,F10*Inputs!B11) | G11: =MAX(0,G10*Inputs!B11)
A12: NOPAT | B12: =B10-B11 | C12: =C10-C11 | D12: =D10-D11 | E12: =E10-E11 | F12: =F10-F11 | G12: =G10-G11
A13: D&A | B13: =B4*Inputs!B31 | C13: =C4*Inputs!B31 | D13: =D4*Inputs!B31 | E13: =E4*Inputs!B31 | F13: =F4*Inputs!B31 | G13: =G4*Inputs!B31
A14: Capex | B14: =B4*Inputs!B32 | C14: =C4*Inputs!B32 | D14: =D4*Inputs!B32 | E14: =E4*Inputs!B32 | F14: =F4*Inputs!B32 | G14: =G4*Inputs!B32
A15: Change in NWC | B15: 0 | C15: =(C4-B4)*Inputs!B33 | D15: =(D4-C4)*Inputs!B33 | E15: =(E4-D4)*Inputs!B33 | F15: =(F4-E4)*Inputs!B33 | G15: =(G4-F4)*Inputs!B33
A16: Free Cash Flow | B16: =B12+B13-B14-B15 | C16: =C12+C13-C14-C15 | D16: =D12+D13-D14-D15 | E16: =E12+E13-E14-E15 | F16: =F12+F13-F14-F15 | G16: =G12+G13-G14-G15
A17: PV of FCF | B17: n.a. | C17: =C16/(1+Inputs!B34)^1 | D17: =D16/(1+Inputs!B34)^2 | E17: =E16/(1+Inputs!B34)^3 | F17: =F16/(1+Inputs!B34)^4 | G17: =G16/(1+Inputs!B34)^5
A18: Terminal Value | G18: =G16*(1+Inputs!B35)/(Inputs!B34-Inputs!B35)
A19: PV of Terminal Value | G19: =G18/(1+Inputs!B34)^5
A20: Enterprise Value (RMB m) | G20: =SUM(C17:G17)+G19
A21: Equity Value (USD m) | G21: =G20/Inputs!B10+Inputs!B8/Inputs!B10-Inputs!B9
A22: Implied Value / ADS | G22: =G21*1000000/Inputs!B7
A25: Base Case | B25: 2025A | C25: 2026E | D25: 2027E | E25: 2028E | F25: 2029E | G25: 2030E
A26: Revenue | B26: =Inputs!B12 | C26: =Inputs!C24 | D26: =C26*(1+Inputs!C25) | E26: =D26*(1+Inputs!C26) | F26: =E26*(1+Inputs!C27) | G26: =F26*(1+Inputs!C28)
A27: Revenue Growth | B27: n.a. | C27: =C26/B26-1 | D27: =D26/C26-1 | E27: =E26/D26-1 | F27: =F26/E26-1 | G27: =G26/F26-1
A28: Gross Margin | B28: =Inputs!B13 | C28: =Inputs!C29 | D28: =Inputs!C29 | E28: =Inputs!C29 | F28: =Inputs!C29 | G28: =Inputs!C29
A29: Gross Profit | B29: =B26*B28 | C29: =C26*C28 | D29: =D26*D28 | E29: =E26*E28 | F29: =F26*F28 | G29: =G26*G28
A30: Operating Expense / Revenue | B30: =(Inputs!B12*Inputs!B13-Inputs!B14)/Inputs!B12 | C30: =((B30)*0.85+Inputs!C30*0.15) | D30: =((C30)*0.65+Inputs!C30*0.35) | E30: =((D30)*0.45+Inputs!C30*0.55) | F30: =((E30)*0.25+Inputs!C30*0.75) | G30: =Inputs!C30
A31: Operating Expense | B31: =B26*B30 | C31: =C26*C30 | D31: =D26*D30 | E31: =E26*E30 | F31: =F26*F30 | G31: =G26*G30
A32: EBIT | B32: =B29-B31 | C32: =C29-C31 | D32: =D29-D31 | E32: =E29-E31 | F32: =F29-F31 | G32: =G29-G31
A33: Tax on Positive EBIT | B33: 0 | C33: =MAX(0,C32*Inputs!B11) | D33: =MAX(0,D32*Inputs!B11) | E33: =MAX(0,E32*Inputs!B11) | F33: =MAX(0,F32*Inputs!B11) | G33: =MAX(0,G32*Inputs!B11)
A34: NOPAT | B34: =B32-B33 | C34: =C32-C33 | D34: =D32-D33 | E34: =E32-E33 | F34: =F32-F33 | G34: =G32-G33
A35: D&A | B35: =B26*Inputs!C31 | C35: =C26*Inputs!C31 | D35: =D26*Inputs!C31 | E35: =E26*Inputs!C31 | F35: =F26*Inputs!C31 | G35: =G26*Inputs!C31
A36: Capex | B36: =B26*Inputs!C32 | C36: =C26*Inputs!C32 | D36: =D26*Inputs!C32 | E36: =E26*Inputs!C32 | F36: =F26*Inputs!C32 | G36: =G26*Inputs!C32
A37: Change in NWC | B37: 0 | C37: =(C26-B26)*Inputs!C33 | D37: =(D26-C26)*Inputs!C33 | E37: =(E26-D26)*Inputs!C33 | F37: =(F26-E26)*Inputs!C33 | G37: =(G26-F26)*Inputs!C33
A38: Free Cash Flow | B38: =B34+B35-B36-B37 | C38: =C34+C35-C36-C37 | D38: =D34+D35-D36-D37 | E38: =E34+E35-E36-E37 | F38: =F34+F35-F36-F37 | G38: =G34+G35-G36-G37
A39: PV of FCF | B39: n.a. | C39: =C38/(1+Inputs!C34)^1 | D39: =D38/(1+Inputs!C34)^2 | E39: =E38/(1+Inputs!C34)^3 | F39: =F38/(1+Inputs!C34)^4 | G39: =G38/(1+Inputs!C34)^5
A40: Terminal Value | G40: =G38*(1+Inputs!C35)/(Inputs!C34-Inputs!C35)
A41: PV of Terminal Value | G41: =G40/(1+Inputs!C34)^5
A42: Enterprise Value (RMB m) | G42: =SUM(C39:G39)+G41
A43: Equity Value (USD m) | G43: =G42/Inputs!B10+Inputs!B8/Inputs!B10-Inputs!B9
...

Sheet Valuation Output
A1: Valuation Output
A2: Outputs are linked to the DCF sheet. Excel will recalculate formulas when opened.
A4: Scenario | B4: Implied Value / ADS | C4: Upside / Downside | D4: Market Price
A5: Bear | B5: ='DCF Model'!G22 | C5: =B5/Inputs!B4-1 | D5: =Inputs!B4
A6: Base | B6: ='DCF Model'!G44 | C6: =B6/Inputs!B4-1 | D6: =Inputs!B4
A7: Bull | B7: ='DCF Model'!G66 | C7: =B7/Inputs!B4-1 | D7: =Inputs!B4
A9: Sensitivity Lens
A10: If the market price sits above Base, the equity is pricing a faster transition from certified aircraft sales to recurring operations and FCF conversion.
A11: If the market price sits below Base, the market is discounting delays, weak route economics, or limited operating leverage.

Sheet Sources
A1: Sources and Model Boundaries
A2: Source | B2: Data Used | C2: Link / Note
A3: EHang FY2025 unaudited results | B3: Revenue, gross margin, operating loss, net loss, cash/investments, delivery volumes | C3: https://ir.ehang.com/static-files/7f221980-3b66-49cb-83c7-1bdabff615fc
A4: EHang FY2025 Form 20-F | B4: Ordinary shares outstanding and RMB/USD translation rate | C4: https://www.sec.gov/Archives/edgar/data/1759783/000119312526226608/d39307d20f.htm
A5: EHang share repurchase announcement | B5: Recent market confidence signal; not included as a valuation driver except potential dilution offset | C5: https://www.globenewswire.com/news-release/2026/06/08/3307952/0/en/EHang-Announces-US-30-Million-Share-Repurchase-Program.html
A6: Policy Alpha model judgment | B6: Scenario assumptions for growth, margins, opex absorption, capex and NWC | C6: Editable; not a forecast guarantee
A8: Important Limitations
A9: This model uses preliminary scenario assumptions because EHang remains in an early commercialization stage. Small changes in delivery scale, route economics, or discount rate can materially change implied value.
A10: The model is not investment advice and should not be read as a target price. It is a framework for testing what must go right for different valuation outcomes.

Sheet Public Data
A1: Public Source Data
A2: This sheet separates disclosed facts from Policy Alpha scenario assumptions.
A4: Category | B4: Metric | C4: Value | D4: Source / Interpretation
A5: FY2025 | B5: Revenue | C5: 509.5 | D5: EHang FY2025 results: RMB509.5m, +11.7% YoY
A6: FY2025 | B6: Deliveries | C6: 221 | D6: 215 EH216 series + 6 VT35
A7: FY2025 | B7: Gross margin | C7: 0.62 | D7: Reported gross margin
A8: FY2025 | B8: Operating loss | C8: -266.3 | D8: GAAP operating loss, RMB m
A9: FY2025 | B9: Net loss | C9: -231 | D9: GAAP net loss, RMB m
A10: FY2025 | B10: Adjusted net income | C10: 29.4 | D10: Non-GAAP adjusted net income, RMB m
A11: Q4 2025 | B11: Revenue | C11: 243.8 | D11: Record quarterly revenue, RMB m
A12: Q4 2025 | B12: Deliveries | C12: 100 | D12: 95 EH216 series + 5 VT35
A13: Q4 2025 | B13: Gross margin | C13: 0.621 | D13: Q4 reported gross margin
A14: Q4 2025 | B14: Net income | C14: 10.5 | D14: First GAAP profitable quarter, RMB m
A15: Balance Sheet | B15: Cash / deposits / short-term investments | C15: 1130 | D15: RMB m, as of Dec 31 2025
A16: Capital Structure | B16: Ordinary shares outstanding | C16: 150242174 | D16: 2025 Form 20-F ordinary shares outstanding
... A19: Market Context | B19: Share repurchase program | C19: 30 | D19: US$30m ADS/ordinary share repurchase authorization over 12 months
A20: Model Boundary | B20: Unknown operating variables | C20: Not disclosed | D20: Route economics, utilization, ticket pricing, battery replacement, insurance cost and operating-service revenue mix are not yet sufficiently disclosed.
